<robot name="2R_robot">
    <link name="base_link">
        <visual>
            <geometry>
                <sphere radius="0.1"/>
            </geometry>
        </visual>
    </link>
    <link name="link1">
        <visual>
            <geometry>
                <cylinder length="1" radius="0.05"/>
            </geometry>
            <origin rpy="0 0 0" xyz="0 0 0.55"/>
        </visual>
    </link>
    <joint name="joint1" type="revolute">
        <parent link="base_link"/>
        <child link="link1"/>
        <origin xyz="0 0 0.05"/>
        <limit effort="200" lower="-3.14" upper="3.14" velocity="1.0"/>
        <axis xyz= "1 0 0"/>
    </joint>
    <link name="link2">
        <visual>
            <geometry>
                <cylinder length="1" radius="0.05"/>
            </geometry>
            <origin rpy="0 0 0" xyz="0 0 0.5"/>
        </visual>
    </link>
    <joint name="joint2" type="revolute">
        <parent link="link1"/>
        <child link="link2"/>
        <origin xyz="0 0 1.05"/>
        <limit effort="200" lower="-3.14" upper="3.14" velocity="1.0"/>
        <axis xyz= "1 0 0"/>
    </joint>
</robot>